<?xml version="1.0"?>
<!--  
  Project Name: ebot 
  Created on:   2.10.2020
  Author: ROS team
  Copyright (c) 2020 eYantra IITB 
-->
<robot name="ebot" xmlns:xacro="http://www.ros.org/wiki/xacro">

	 <link
    name="drone_base">
    <inertial>
      <origin
   xyz="0 0.0 0.12"
        rpy="0 0 0" />
      <mass
        value="1.2" />
    <!--   <inertia
        ixx="0.0077465"
        ixy="0.0005698"
        ixz="0.0049745"
        iyy="0.03055"
        iyz="-4.0532E-05"
        izz="0.030588" /> -->
         <inertia ixx="0.356" ixy="0" ixz="0" iyy="0.9443" iyz="0" izz="1.008"/>
    </inertial>
    <visual>
      <origin
        xyz="0 0 0"
        rpy="0 0 0" />
      <geometry>
        <mesh
          filename="package://drone_gazebo/mesh/nopro_drone.stl" scale="0.5 0.5 0.5" />
      </geometry>
      <material
        name="">
        <color
          rgba="0.79216 0.81961 0.93333 1" />
      </material>
    </visual>
    <collision>
    <origin
        xyz="0 0.0 0.12"
        rpy="0 0 0" />
      <geometry>
     <box size="0.585 0.30 0.25"/>
      </geometry>
    </collision>
  </link>

      <!-- Prop one joint  -->

  	  <link name="prop1">
    		<inertial>
			  <origin
			    xyz="0 0 0"
			    rpy="0 0 0" />
			  <mass
			    value="0.1" />
			 <!--  <inertia
			    ixx="0.0012203"
			    ixy="-1.8327E-07"
			    ixz="1.356E-08"
			    iyy="0.0022215"
			    iyz="3.3883E-09"
			    izz="0.001221" /> -->
          			<inertia ixx="0.003" ixy="0" ixz="0" iyy="0.0030" iyz="0" izz="0.0035"/>
    		</inertial>
    <visual>
      <origin
        xyz="0 0 0"
        rpy="0 0 0" />
	      <geometry>
	        <mesh
	          filename="package://drone_gazebo/mesh/prop_ccw.stl" scale="3.5 3.5 3.5" />
	      </geometry>
	      <material
	        name="">
	        <color
	          rgba="0.79216 0.81961 0.93333 1" />
	      </material>
    </visual>
    <collision>
		  <origin
		     xyz="0 0 0"
		    rpy="1.57 1.57 0" />
		  <geometry>
		     <cylinder length="0.05" radius="0.1"/>
		  </geometry>
    </collision>
  </link>
  <joint
    name="prop_base_one"
    type="continuous">
    <origin
      xyz="2.27 1.975 0.67"
      rpy="0 0 0" />
    <parent
      link="drone_base" />
    <child
      link="prop1" />
    <axis
      xyz="0 0 1" />
  </joint>
    <!-- end prop one -->



    <!-- Prop TWO joint  -->

      <link name="prop2">
        <inertial>
        <origin
          xyz="0 0 0"
          rpy="0 0 0" />
        <mass
          value="0.1" />
       <!--  <inertia
          ixx="0.0012203"
          ixy="-1.8327E-07"
          ixz="1.356E-08"
          iyy="0.0022215"
          iyz="3.3883E-09"
          izz="0.001221" /> -->
                <inertia ixx="0.003" ixy="0" ixz="0" iyy="0.0030" iyz="0" izz="0.0035"/>
        </inertial>
    <visual>
      <origin
        xyz="0 0 0"
        rpy="0 0 0" />
        <geometry>
          <mesh
            filename="package://drone_gazebo/mesh/prop.stl" scale="3.5 3.5 3.5" />
        </geometry>
        <material
          name="">
          <color
            rgba="0.79216 0.81961 0.93333 1" />
        </material>
    </visual>
    <collision>
      <origin
         xyz="0 0 0"
        rpy="1.57 1.57 0" />
      <geometry>
         <cylinder length="0.05" radius="0.1"/>
      </geometry>
    </collision>
  </link>
  <joint
    name="prop_base_two"
    type="continuous">
    <origin
      xyz="2.27 -1.975 0.67"
      rpy="0 0 0" />
    <parent
      link="drone_base" />
    <child
      link="prop2" />
    <axis
      xyz="0 0 -1" />
  </joint>
    <!-- end prop two -->



    <!-- Prop three joint  -->

      <link name="prop3">
        <inertial>
        <origin
          xyz="0 0 0"
          rpy="0 0 0" />
        <mass
          value="0.1" />
       <!--  <inertia
          ixx="0.0012203"
          ixy="-1.8327E-07"
          ixz="1.356E-08"
          iyy="0.0022215"
          iyz="3.3883E-09"
          izz="0.001221" /> -->
                <inertia ixx="0.003" ixy="0" ixz="0" iyy="0.0030" iyz="0" izz="0.0035"/>
        </inertial>
    <visual>
      <origin
        xyz="0 0 0"
        rpy="0 0 0" />
        <geometry>
          <mesh
            filename="package://drone_gazebo/mesh/prop_ccw.stl" scale="3.5 3.5 3.5" />
        </geometry>
        <material
          name="">
          <color
            rgba="0.79216 0.81961 0.93333 1" />
        </material>
    </visual>
    <collision>
      <origin
         xyz="0 0 0"
        rpy="1.57 1.57 0" />
      <geometry>
         <cylinder length="0.05" radius="0.1"/>
      </geometry>
    </collision>
  </link>
  <joint
    name="prop_base_three"
    type="continuous">
    <origin
      xyz="-1.2 -1.975 0.67"
      rpy="0 0 0" />
    <parent
      link="drone_base" />
    <child
      link="prop3" />
    <axis
      xyz="0 0 1" />
  </joint>
    <!-- end prop three -->





    <!-- Prop TWO joint  -->

      <link name="prop4">
        <inertial>
        <origin
          xyz="0 0 0"
          rpy="0 0 0" />
        <mass
          value="0.1" />
       <!--  <inertia
          ixx="0.0012203"
          ixy="-1.8327E-07"
          ixz="1.356E-08"
          iyy="0.0022215"
          iyz="3.3883E-09"
          izz="0.001221" /> -->
                <inertia ixx="0.003" ixy="0" ixz="0" iyy="0.0030" iyz="0" izz="0.0035"/>
        </inertial>
    <visual>
      <origin
        xyz="0 0 0"
        rpy="0 0 0" />
        <geometry>
          <mesh
            filename="package://drone_gazebo/mesh/prop.stl" scale="3.5 3.5 3.5" />
        </geometry>
        <material
          name="">
          <color
            rgba="0.79216 0.81961 0.93333 1" />
        </material>
    </visual>
    <collision>
      <origin
         xyz="0 0 0"
        rpy="1.57 1.57 0" />
      <geometry>
         <cylinder length="0.05" radius="0.1"/>
      </geometry>
    </collision>
  </link>
  <joint
    name="prop_base_four"
    type="continuous">
    <origin
      xyz="-1.2 1.975 0.67"
      rpy="0 0 0" />
    <parent
      link="drone_base" />
    <child
      link="prop4" />
    <axis
      xyz="0 0 -1" />
  </joint>
    <!-- end prop two -->


</robot>